Traceback (most recent call last):
  File "d:\programdata\anaconda3\lib\site-packages\jupyter_cache\executors\utils.py", line 56, in single_nb_execution
    record_timing=False,
  File "d:\programdata\anaconda3\lib\site-packages\nbclient\client.py", line 1087, in execute
    return NotebookClient(nb=nb, resources=resources, km=km, **kwargs).execute()
  File "d:\programdata\anaconda3\lib\site-packages\nbclient\util.py", line 74, in wrapped
    return just_run(coro(*args, **kwargs))
  File "d:\programdata\anaconda3\lib\site-packages\nbclient\util.py", line 53, in just_run
    return loop.run_until_complete(coro)
  File "D:\ProgramData\Anaconda3\lib\asyncio\base_events.py", line 587, in run_until_complete
    return future.result()
  File "d:\programdata\anaconda3\lib\site-packages\nbclient\client.py", line 541, in async_execute
    cell, index, execution_count=self.code_cells_executed + 1
  File "d:\programdata\anaconda3\lib\site-packages\nbclient\client.py", line 832, in async_execute_cell
    self._check_raise_for_error(cell, exec_reply)
  File "d:\programdata\anaconda3\lib\site-packages\nbclient\client.py", line 740, in _check_raise_for_error
    raise CellExecutionError.from_cell_and_msg(cell, exec_reply['content'])
nbclient.exceptions.CellExecutionError: An error occurred while executing the following cell:
------------------
# Fixing random state for reproducibility
np.random.seed(19680801)

N = 10
data = [np.logspace(0, 1, 100) + np.random.randn(100) + ii for ii in range(N)]
data = np.array(data).T
cmap = plt.cm.coolwarm
rcParams['axes.prop_cycle'] = cycler(color=cmap(np.linspace(0, 1, N)))


from matplotlib.lines import Line2D
custom_lines = [Line2D([0], [0], color=cmap(0.), lw=4),
                Line2D([0], [0], color=cmap(.5), lw=4),
                Line2D([0], [0], color=cmap(1.), lw=4)]

fig, ax = plt.subplots(figsize=(10, 5))
lines = ax.plot(data)
ax.legend(custom_lines, ['Cold', 'Medium', 'Hot']);
------------------

[1;31m---------------------------------------------------------------------------[0m
[1;31mNameError[0m                                 Traceback (most recent call last)
[1;32m<ipython-input-1-aaee2cc66c69>[0m in [0;36m<module>[1;34m[0m
[0;32m      1[0m [1;31m# Fixing random state for reproducibility[0m[1;33m[0m[1;33m[0m[1;33m[0m[0m
[1;32m----> 2[1;33m [0mnp[0m[1;33m.[0m[0mrandom[0m[1;33m.[0m[0mseed[0m[1;33m([0m[1;36m19680801[0m[1;33m)[0m[1;33m[0m[1;33m[0m[0m
[0m[0;32m      3[0m [1;33m[0m[0m
[0;32m      4[0m [0mN[0m [1;33m=[0m [1;36m10[0m[1;33m[0m[1;33m[0m[0m
[0;32m      5[0m [0mdata[0m [1;33m=[0m [1;33m[[0m[0mnp[0m[1;33m.[0m[0mlogspace[0m[1;33m([0m[1;36m0[0m[1;33m,[0m [1;36m1[0m[1;33m,[0m [1;36m100[0m[1;33m)[0m [1;33m+[0m [0mnp[0m[1;33m.[0m[0mrandom[0m[1;33m.[0m[0mrandn[0m[1;33m([0m[1;36m100[0m[1;33m)[0m [1;33m+[0m [0mii[0m [1;32mfor[0m [0mii[0m [1;32min[0m [0mrange[0m[1;33m([0m[0mN[0m[1;33m)[0m[1;33m][0m[1;33m[0m[1;33m[0m[0m

[1;31mNameError[0m: name 'np' is not defined
NameError: name 'np' is not defined

